<?xml version="1.0" encoding="utf-8"?>
<!-- This URDF was automatically created by SolidWorks to URDF Exporter! Originally created by Stephen Brawner (brawner@gmail.com) 
     Commit Version: 1.6.0-1-g15f4949  Build Version: 1.6.7594.29634
     For more information, please see http://wiki.ros.org/sw_urdf_exporter -->
<robot
  name="freehand_description">
  <link
    name="base_link">
    <inertial>
      <origin
        xyz="0 0 0"
        rpy="0 0 0" />
      <mass
        value="0.91778" />
      <inertia
        ixx="0.0018592"
        ixy="6.239E-05"
        ixz="-6.688E-05"
        iyy="0.0015814"
        iyz="3.163E-05"
        izz="0.00064901" />
    </inertial>
    <visual>
      <origin
        xyz="0 0 0"
        rpy="0 0 0" />
      <geometry>
        <mesh
          filename="base_link.STL" />
      </geometry>
      <material
        name="">
        <color
          rgba="0.7 0.8 0.9 1" />
      </material>
    </visual>
    <collision>
      <origin
        xyz="0 0 0"
        rpy="0 0 0" />
      <geometry>
        <mesh
          filename="base_link.STL" />
      </geometry>
    </collision>
  </link>
  <link
    name="f11">
    <inertial>
      <origin
        xyz="0 0.00069742 -0.0093798"
        rpy="0 0 0" />
      <mass
        value="0.0033015" />
      <inertia
        ixx="2E-07"
        ixy="0"
        ixz="0"
        iyy="3.1E-07"
        iyz="1E-08"
        izz="1.4E-07" />
    </inertial>
    <visual>
      <origin
        xyz="0 0 0"
        rpy="0 0 0" />
      <geometry>
        <mesh
          filename="f11.STL" />
      </geometry>
      <material
        name="">
        <color
          rgba="0.65 0.8 0.9 1" />
      </material>
    </visual>
    <collision>
      <origin
        xyz="0 0 0"
        rpy="0 0 0" />
      <geometry>
        <mesh
          filename="f11.STL" />
      </geometry>
    </collision>
  </link>
  <joint
    name="f11_joint"
    type="revolute">
    <origin
      xyz="-0.022466 0.027654 0.043657"
      rpy="1.5708 0.02618 1.5708" />
    <parent
      link="base_link" />
    <child
      link="f11" />
    <axis
      xyz="0 0 1" />
    <limit
      lower="-0.4"
      upper="0.4"
      effort="0"
      velocity="0" />
  </joint>
  <link
    name="f12">
    <inertial>
      <origin
        xyz="0.026032 -0.0074611 2.268E-05"
        rpy="0 0 0" />
      <mass
        value="0.058465" />
      <inertia
        ixx="4.34E-06"
        ixy="-4.9E-06"
        ixz="5.3E-07"
        iyy="1.396E-05"
        iyz="-2.1E-07"
        izz="1.633E-05" />
    </inertial>
    <visual>
      <origin
        xyz="0 0 0"
        rpy="0 0 0" />
      <geometry>
        <mesh
          filename="f12.STL" />
      </geometry>
      <material
        name="">
        <color
          rgba="0.6 0.8 0.9 1" />
      </material>
    </visual>
    <collision>
      <origin
        xyz="0 0 0"
        rpy="0 0 0" />
      <geometry>
        <mesh
          filename="f12.STL" />
      </geometry>
    </collision>
  </link>
  <joint
    name="f12_joint"
    type="revolute">
    <origin
      xyz="0 0 0"
      rpy="1.5708 0 1.5708" />
    <parent
      link="f11" />
    <child
      link="f12" />
    <axis
      xyz="0 0 1" />
    <limit
      lower="0"
      upper="2.09"
      effort="0"
      velocity="0" />
  </joint>
  <link
    name="f13">
    <inertial>
      <origin
        xyz="0.0090975 -0.0015069 0.0013415"
        rpy="0 0 0" />
      <mass
        value="0.014574" />
      <inertia
        ixx="9.3E-07"
        ixy="-3.2E-07"
        ixz="-1.8E-07"
        iyy="2.04E-06"
        iyz="6E-08"
        izz="1.81E-06" />
    </inertial>
    <visual>
      <origin
        xyz="0 0 0"
        rpy="0 0 0" />
      <geometry>
        <mesh
          filename="f13.STL" />
      </geometry>
      <material
        name="">
        <color
          rgba="0.55 0.8 0.9 1" />
      </material>
    </visual>
    <collision>
      <origin
        xyz="0 0 0"
        rpy="0 0 0" />
      <geometry>
        <mesh
          filename="f13.STL" />
      </geometry>
    </collision>
  </link>
  <joint
    name="f13_joint"
    type="revolute">
    <origin
      xyz="0.048883 -0.018383 0"
      rpy="0 0 0" />
    <parent
      link="f12" />
    <child
      link="f13" />
    <axis
      xyz="0 0 1" />
    <limit
      lower="0"
      upper="1.744"
      effort="0"
      velocity="0" />
  </joint>
  <link
    name="f14">
    <inertial>
      <origin
        xyz="0.007749 -0.0041898 -0.00072552"
        rpy="0 0 0" />
      <mass
        value="0.0055228" />
      <inertia
        ixx="2.3E-07"
        ixy="-1.5E-07"
        ixz="2E-08"
        iyy="4E-07"
        iyz="-1E-08"
        izz="5E-07" />
    </inertial>
    <visual>
      <origin
        xyz="0 0 0"
        rpy="0 0 0" />
      <geometry>
        <mesh
          filename="f14.STL" />
      </geometry>
      <material
        name="">
        <color
          rgba="0.5 0.8 0.9 1" />
      </material>
    </visual>
    <collision>
      <origin
        xyz="0 0 0"
        rpy="0 0 0" />
      <geometry>
        <mesh
          filename="f14.STL" />
      </geometry>
    </collision>
  </link>
  <joint
    name="f14_joint"
    type="revolute">
    <origin
      xyz="0.0284 -0.0092477 0"
      rpy="0 0 0" />
    <parent
      link="f13" />
    <child
      link="f14" />
    <axis
      xyz="0 0 1" />
    <limit
      lower="0"
      upper="1.744"
      effort="0"
      velocity="0" />
  </joint>
  <link
    name="f14_touch">
    <inertial>
      <origin
        xyz="-0.010332 -0.0011919 -1.5694E-06"
        rpy="0 0 0" />
      <mass
        value="5.5227E-30" />
      <inertia
        ixx="1.8111E-30"
        ixy="8.9727E-30"
        ixz="3.0827E-30"
        iyy="2.1865E-30"
        iyz="-8.5132E-30"
        izz="3.0253E-30" />
    </inertial>
    <!--visual>
      <origin
        xyz="0 0 0"
        rpy="0 0 0" />
      <geometry>
        <mesh
          filename="f14_touch.STL" />
      </geometry>
      <material
        name="">
        <color
          rgba="0.79216 0.81961 0.93333 1" />
      </material>
    </visual>
    <collision>
      <origin
        xyz="0 0 0"
        rpy="0 0 0" />
      <geometry>
        <mesh
          filename="f14_touch.STL" />
      </geometry>
    </collision-->
  </link>
  <joint
    name="f14_touch_joint"
    type="fixed">
    <origin
      xyz="0.019695 -0.0034802 0"
      rpy="0 0 0" />
    <parent
      link="f14" />
    <child
      link="f14_touch" />
    <axis
      xyz="0 0 0" />
  </joint>
  <link
    name="f21">
    <inertial>
      <origin
        xyz="0 0.00069742 -0.0093798"
        rpy="0 0 0" />
      <mass
        value="0.0033015" />
      <inertia
        ixx="2E-07"
        ixy="0"
        ixz="0"
        iyy="3.1E-07"
        iyz="1E-08"
        izz="1.4E-07" />
    </inertial>
    <visual>
      <origin
        xyz="0 0 0"
        rpy="0 0 0" />
      <geometry>
        <mesh
          filename="f21.STL" />
      </geometry>
      <material
        name="">
        <color
          rgba="0.7 0.75 0.9 1" />
      </material>
    </visual>
    <collision>
      <origin
        xyz="0 0 0"
        rpy="0 0 0" />
      <geometry>
        <mesh
          filename="f21.STL" />
      </geometry>
    </collision>
  </link>
  <joint
    name="f21_joint"
    type="revolute">
    <origin
      xyz="-0.022466 0.0022583 0.053546"
      rpy="1.5708 0 1.5708" />
    <parent
      link="base_link" />
    <child
      link="f21" />
    <axis
      xyz="0 0 1" />
    <limit
      lower="-0.4"
      upper="0.4"
      effort="0"
      velocity="0" />
  </joint>
  <link
    name="f22">
    <inertial>
      <origin
        xyz="0.026032 -0.0074611 2.268E-05"
        rpy="0 0 0" />
      <mass
        value="0.058465" />
      <inertia
        ixx="4.34E-06"
        ixy="-4.9E-06"
        ixz="5.3E-07"
        iyy="1.396E-05"
        iyz="-2.1E-07"
        izz="1.633E-05" />
    </inertial>
    <visual>
      <origin
        xyz="0 0 0"
        rpy="0 0 0" />
      <geometry>
        <mesh
          filename="f22.STL" />
      </geometry>
      <material
        name="">
        <color
          rgba="0.7 0.7 0.9 1" />
      </material>
    </visual>
    <collision>
      <origin
        xyz="0 0 0"
        rpy="0 0 0" />
      <geometry>
        <mesh
          filename="f22.STL" />
      </geometry>
    </collision>
  </link>
  <joint
    name="f22_joint"
    type="revolute">
    <origin
      xyz="0 0 0"
      rpy="1.5708 0 1.5708" />
    <parent
      link="f21" />
    <child
      link="f22" />
    <axis
      xyz="0 0 1" />
    <limit
      lower="0"
      upper="2.09"
      effort="0"
      velocity="0" />
  </joint>
  <link
    name="f23">
    <inertial>
      <origin
        xyz="0.0090975 -0.0015069 0.0013415"
        rpy="0 0 0" />
      <mass
        value="0.014574" />
      <inertia
        ixx="9.3E-07"
        ixy="-3.2E-07"
        ixz="-1.8E-07"
        iyy="2.04E-06"
        iyz="6E-08"
        izz="1.81E-06" />
    </inertial>
    <visual>
      <origin
        xyz="0 0 0"
        rpy="0 0 0" />
      <geometry>
        <mesh
          filename="f23.STL" />
      </geometry>
      <material
        name="">
        <color
          rgba="0.7 0.65 0.9 1" />
      </material>
    </visual>
    <collision>
      <origin
        xyz="0 0 0"
        rpy="0 0 0" />
      <geometry>
        <mesh
          filename="f23.STL" />
      </geometry>
    </collision>
  </link>
  <joint
    name="f23_joint"
    type="revolute">
    <origin
      xyz="0.048883 -0.018383 0"
      rpy="0 0 0" />
    <parent
      link="f22" />
    <child
      link="f23" />
    <axis
      xyz="0 0 1" />
    <limit
      lower="0"
      upper="1.744"
      effort="0"
      velocity="0" />
  </joint>
  <link
    name="f24">
    <inertial>
      <origin
        xyz="0.007749 -0.0041898 -0.00072552"
        rpy="0 0 0" />
      <mass
        value="0.0055228" />
      <inertia
        ixx="2.3E-07"
        ixy="-1.5E-07"
        ixz="2E-08"
        iyy="4E-07"
        iyz="-1E-08"
        izz="5E-07" />
    </inertial>
    <visual>
      <origin
        xyz="0 0 0"
        rpy="0 0 0" />
      <geometry>
        <mesh
          filename="f24.STL" />
      </geometry>
      <material
        name="">
        <color
          rgba="0.7 0.6 0.9 1" />
      </material>
    </visual>
    <collision>
      <origin
        xyz="0 0 0"
        rpy="0 0 0" />
      <geometry>
        <mesh
          filename="f24.STL" />
      </geometry>
    </collision>
  </link>
  <joint
    name="f24_joint"
    type="revolute">
    <origin
      xyz="0.0284 -0.0092477 0"
      rpy="0 0 0" />
    <parent
      link="f23" />
    <child
      link="f24" />
    <axis
      xyz="0 0 1" />
    <limit
      lower="0"
      upper="1.744"
      effort="0"
      velocity="0" />
  </joint>
  <link
    name="f24_touch">
    <inertial>
      <origin
        xyz="-0.010332 -0.0011919 -1.5701E-06"
        rpy="0 0 0" />
      <mass
        value="5.5227E-30" />
      <inertia
        ixx="1.8111E-30"
        ixy="8.9727E-30"
        ixz="3.0812E-30"
        iyy="2.1865E-30"
        iyz="-8.5218E-30"
        izz="3.0253E-30" />
    </inertial>
    <!--visual>
      <origin
        xyz="0 0 0"
        rpy="0 0 0" />
      <geometry>
        <mesh
          filename="f24_touch.STL" />
      </geometry>
      <material
        name="">
        <color
          rgba="0.79216 0.81961 0.93333 1" />
      </material>
    </visual>
    <collision>
      <origin
        xyz="0 0 0"
        rpy="0 0 0" />
      <geometry>
        <mesh
          filename="f24_touch.STL" />
      </geometry>
    </collision-->
  </link>
  <joint
    name="f24_touch_joint"
    type="fixed">
    <origin
      xyz="0.019695 -0.0034802 0"
      rpy="0 0 0" />
    <parent
      link="f24" />
    <child
      link="f24_touch" />
    <axis
      xyz="0 0 0" />
  </joint>
  <link
    name="f31">
    <inertial>
      <origin
        xyz="-6.964E-05 -0.00044078 -0.012759"
        rpy="0 0 0" />
      <mass
        value="0.0085521" />
      <inertia
        ixx="7.6E-07"
        ixy="0"
        ixz="0"
        iyy="7.6E-07"
        iyz="4E-08"
        izz="1.3E-07" />
    </inertial>
    <visual>
      <origin
        xyz="0 0 0"
        rpy="0 0 0" />
      <geometry>
        <mesh
          filename="f31.STL" />
      </geometry>
      <material
        name="">
        <color
          rgba="0.7 0.8 0.85 1" />
      </material>
    </visual>
    <collision>
      <origin
        xyz="0 0 0"
        rpy="0 0 0" />
      <geometry>
        <mesh
          filename="f31.STL" />
      </geometry>
    </collision>
  </link>
  <joint
    name="f31_joint"
    type="revolute">
    <origin
      xyz="-0.021466 -0.017542 0.047798"
      rpy="1.5708 0 1.5708" />
    <parent
      link="base_link" />
    <child
      link="f31" />
    <axis
      xyz="0 0 1" />
    <limit
      lower="-0.4"
      upper="0.4"
      effort="0"
      velocity="0" />
  </joint>
  <link
    name="f32">
    <inertial>
      <origin
        xyz="0.025132 0.0031733 -8.727E-05"
        rpy="0 0 0" />
      <mass
        value="0.01244" />
      <inertia
        ixx="4.5E-07"
        ixy="-1.2E-07"
        ixz="0"
        iyy="2.29E-06"
        iyz="0"
        izz="2.41E-06" />
    </inertial>
    <visual>
      <origin
        xyz="0 0 0"
        rpy="0 0 0" />
      <geometry>
        <mesh
          filename="f32.STL" />
      </geometry>
      <material
        name="">
        <color
          rgba="0.7 0.8 0.8 1" />
      </material>
    </visual>
    <collision>
      <origin
        xyz="0 0 0"
        rpy="0 0 0" />
      <geometry>
        <mesh
          filename="f32.STL" />
      </geometry>
    </collision>
  </link>
  <joint
    name="f32_joint"
    type="revolute">
    <origin
      xyz="0 0 0"
      rpy="1.5708 0 1.5708" />
    <parent
      link="f31" />
    <child
      link="f32" />
    <axis
      xyz="0 0 1" />
    <limit
      lower="0"
      upper="1.744"
      effort="0"
      velocity="0" />
  </joint>
  <link
    name="f33">
    <inertial>
      <origin
        xyz="0.010032 -0.00058707 -9.093E-05"
        rpy="0 0 0" />
      <mass
        value="0.0071009" />
      <inertia
        ixx="2.8E-07"
        ixy="-8E-08"
        ixz="0"
        iyy="6.9E-07"
        iyz="0"
        izz="7E-07" />
    </inertial>
    <visual>
      <origin
        xyz="0 0 0"
        rpy="0 0 0" />
      <geometry>
        <mesh
          filename="f33.STL" />
      </geometry>
      <material
        name="">
        <color
          rgba="0.7 0.8 0.75 1" />
      </material>
    </visual>
    <collision>
      <origin
        xyz="0 0 0"
        rpy="0 0 0" />
      <geometry>
        <mesh
          filename="f33.STL" />
      </geometry>
    </collision>
  </link>
  <joint
    name="f33_joint"
    type="revolute">
    <origin
      xyz="0.044995 0.00066781 0"
      rpy="0 0 0" />
    <parent
      link="f32" />
    <child
      link="f33" />
    <axis
      xyz="0 0 1" />
    <limit
      lower="0"
      upper="1.744"
      effort="0"
      velocity="0" />
  </joint>
  <link
    name="f34">
    <inertial>
      <origin
        xyz="0.010482 -0.0030354 -1.03E-05"
        rpy="0 0 0" />
      <mass
        value="0.0049513" />
      <inertia
        ixx="1.3E-07"
        ixy="-6E-08"
        ixz="0"
        iyy="3.2E-07"
        iyz="0"
        izz="3.7E-07" />
    </inertial>
    <visual>
      <origin
        xyz="0 0 0"
        rpy="0 0 0" />
      <geometry>
        <mesh
          filename="f34.STL" />
      </geometry>
      <material
        name="">
        <color
          rgba="0.7 0.8 0.7 1" />
      </material>
    </visual>
    <collision>
      <origin
        xyz="0 0 0"
        rpy="0 0 0" />
      <geometry>
        <mesh
          filename="f34.STL" />
      </geometry>
    </collision>
  </link>
  <joint
    name="f34_joint"
    type="revolute">
    <origin
      xyz="0.024601 -0.0044465 0"
      rpy="0 0 0" />
    <parent
      link="f33" />
    <child
      link="f34" />
    <axis
      xyz="0 0 1" />
    <limit
      lower="0"
      upper="1.744"
      effort="0"
      velocity="0" />
  </joint>
  <link
    name="f34_touch">
    <inertial>
      <origin
        xyz="-0.0083273 -0.0042825 -1.427E-06"
        rpy="0 0 0" />
      <mass
        value="4.9512E-30" />
      <inertia
        ixx="1.1521E-30"
        ixy="4.836E-30"
        ixz="-1.3182E-30"
        iyy="1.7954E-30"
        iyz="8.5895E-30"
        izz="2.2159E-30" />
    </inertial>
    <!--visual>
      <origin
        xyz="0 0 0"
        rpy="0 0 0" />
      <geometry>
        <mesh
          filename="f34_touch.STL" />
      </geometry>
      <material
        name="">
        <color
          rgba="0.79216 0.81961 0.93333 1" />
      </material>
    </visual>
    <collision>
      <origin
        xyz="0 0 0"
        rpy="0 0 0" />
      <geometry>
        <mesh
          filename="f34_touch.STL" />
      </geometry>
    </collision-->
  </link>
  <joint
    name="f34_touch_joint"
    type="fixed">
    <origin
      xyz="0.021134 0.0011803 0"
      rpy="0 0 0" />
    <parent
      link="f34" />
    <child
      link="f34_touch" />
    <axis
      xyz="0 0 0" />
  </joint>
  <link
    name="f41">
    <inertial>
      <origin
        xyz="-6.964E-05 -0.00044078 -0.012759"
        rpy="0 0 0" />
      <mass
        value="0.0085521" />
      <inertia
        ixx="7.6E-07"
        ixy="0"
        ixz="0"
        iyy="7.6E-07"
        iyz="4E-08"
        izz="1.3E-07" />
    </inertial>
    <visual>
      <origin
        xyz="0 0 0"
        rpy="0 0 0" />
      <geometry>
        <mesh
          filename="f41.STL" />
      </geometry>
      <material
        name="">
        <color
          rgba="0.65 0.75 0.9 1" />
      </material>
    </visual>
    <collision>
      <origin
        xyz="0 0 0"
        rpy="0 0 0" />
      <geometry>
        <mesh
          filename="f41.STL" />
      </geometry>
    </collision>
  </link>
  <joint
    name="f41_joint"
    type="revolute">
    <origin
      xyz="-0.021466 -0.034458 0.032384"
      rpy="1.5708 -0.034907 1.5708" />
    <parent
      link="base_link" />
    <child
      link="f41" />
    <axis
      xyz="0 0 1" />
    <limit
      lower="-0.4"
      upper="0.4"
      effort="0"
      velocity="0" />
  </joint>
  <link
    name="f42">
    <inertial>
      <origin
        xyz="0.021044 0.0035949 -7.944E-05"
        rpy="0 0 0" />
      <mass
        value="0.0096409" />
      <inertia
        ixx="3.5E-07"
        ixy="-3E-08"
        ixz="0"
        iyy="1.24E-06"
        iyz="0"
        izz="1.35E-06" />
    </inertial>
    <visual>
      <origin
        xyz="0 0 0"
        rpy="0 0 0" />
      <geometry>
        <mesh
          filename="f42.STL" />
      </geometry>
      <material
        name="">
        <color
          rgba="0.6 0.7 0.9 1" />
      </material>
    </visual>
    <collision>
      <origin
        xyz="0 0 0"
        rpy="0 0 0" />
      <geometry>
        <mesh
          filename="f42.STL" />
      </geometry>
    </collision>
  </link>
  <joint
    name="f42_joint"
    type="revolute">
    <origin
      xyz="0 0 0"
      rpy="1.5708 0 1.5708" />
    <parent
      link="f41" />
    <child
      link="f42" />
    <axis
      xyz="0 0 1" />
    <limit
      lower="0"
      upper="1.6"
      effort="0"
      velocity="0" />
  </joint>
  <link
    name="f43">
    <inertial>
      <origin
        xyz="0.010032 -0.00058707 -9.093E-05"
        rpy="0 0 0" />
      <mass
        value="0.0071009" />
      <inertia
        ixx="2.8E-07"
        ixy="-8E-08"
        ixz="0"
        iyy="6.9E-07"
        iyz="0"
        izz="7E-07" />
    </inertial>
    <visual>
      <origin
        xyz="0 0 0"
        rpy="0 0 0" />
      <geometry>
        <mesh
          filename="f43.STL" />
      </geometry>
      <material
        name="">
        <color
          rgba="0.55 0.65 0.9 1" />
      </material>
    </visual>
    <collision>
      <origin
        xyz="0 0 0"
        rpy="0 0 0" />
      <geometry>
        <mesh
          filename="f43.STL" />
      </geometry>
    </collision>
  </link>
  <joint
    name="f43_joint"
    type="revolute">
    <origin
      xyz="0.035975 0.001338 0"
      rpy="0 0 0" />
    <parent
      link="f42" />
    <child
      link="f43" />
    <axis
      xyz="0 0 1" />
    <limit
      lower="0"
      upper="1.744"
      effort="0"
      velocity="0" />
  </joint>
  <link
    name="f44">
    <inertial>
      <origin
        xyz="0.010482 -0.0030354 -1.03E-05"
        rpy="0 0 0" />
      <mass
        value="0.0049513" />
      <inertia
        ixx="1.3E-07"
        ixy="-6E-08"
        ixz="0"
        iyy="3.2E-07"
        iyz="0"
        izz="3.7E-07" />
    </inertial>
    <visual>
      <origin
        xyz="0 0 0"
        rpy="0 0 0" />
      <geometry>
        <mesh
          filename="f44.STL" />
      </geometry>
      <material
        name="">
        <color
          rgba="0.5 0.6 0.9 1" />
      </material>
    </visual>
    <collision>
      <origin
        xyz="0 0 0"
        rpy="0 0 0" />
      <geometry>
        <mesh
          filename="f44.STL" />
      </geometry>
    </collision>
  </link>
  <joint
    name="f44_joint"
    type="revolute">
    <origin
      xyz="0.024621 -0.004339 0"
      rpy="0 0 0" />
    <parent
      link="f43" />
    <child
      link="f44" />
    <axis
      xyz="0 0 1" />
    <limit
      lower="0"
      upper="1.744"
      effort="0"
      velocity="0" />
  </joint>
  <link
    name="f44_touch">
    <inertial>
      <origin
        xyz="-0.0083659 -0.0043407 -1.419E-06"
        rpy="0 0 0" />
      <mass
        value="5.0077E-30" />
      <inertia
        ixx="1.1521E-30"
        ixy="4.8481E-30"
        ixz="-1.3705E-30"
        iyy="1.824E-30"
        iyz="8.7785E-30"
        izz="2.2404E-30" />
    </inertial>
    <!--visual>
      <origin
        xyz="0 0 0"
        rpy="0 0 0" />
      <geometry>
        <mesh
          filename="f44_touch.STL" />
      </geometry>
      <material
        name="">
        <color
          rgba="0.79216 0.81961 0.93333 1" />
      </material>
    </visual>
    <collision>
      <origin
        xyz="0 0 0"
        rpy="0 0 0" />
      <geometry>
        <mesh
          filename="f44_touch.STL" />
      </geometry>
    </collision-->
  </link>
  <joint
    name="f44_touch_joint"
    type="fixed">
    <origin
      xyz="0.021123 0.0013734 0"
      rpy="0 0 0" />
    <parent
      link="f44" />
    <child
      link="f44_touch" />
    <axis
      xyz="0 0 0" />
  </joint>
  <link
    name="f51">
    <inertial>
      <origin
        xyz="0.0053991 0.0016936 0.01157"
        rpy="0 0 0" />
      <mass
        value="0.022542" />
      <inertia
        ixx="3.06E-06"
        ixy="4.2E-07"
        ixz="3.3E-07"
        iyy="5.17E-06"
        iyz="1E-08"
        izz="3.39E-06" />
    </inertial>
    <visual>
      <origin
        xyz="0 0 0"
        rpy="0 0 0" />
      <geometry>
        <mesh
          filename="f51.STL" />
      </geometry>
      <material
        name="">
        <color
          rgba="0.65 0.8 0.85 1" />
      </material>
    </visual>
    <collision>
      <origin
        xyz="0 0 0"
        rpy="0 0 0" />
      <geometry>
        <mesh
          filename="f51.STL" />
      </geometry>
    </collision>
  </link>
  <joint
    name="f51_joint"
    type="revolute">
    <origin
      xyz="-0.00049657 0.0084524 -0.066754"
      rpy="0 0 0" />
    <parent
      link="base_link" />
    <child
      link="f51" />
    <axis
      xyz="0 0 -1" />
    <limit
      lower="0"
      upper="1.5"
      effort="0"
      velocity="0" />
  </joint>
  <link
    name="f52">
    <inertial>
      <origin
        xyz="0.03317 -0.0064258 -0.00083733"
        rpy="0 0 0" />
      <mass
        value="0.12909" />
      <inertia
        ixx="1.628E-05"
        ixy="-6.22E-06"
        ixz="-3.01E-06"
        iyy="6.413E-05"
        iyz="1.13E-06"
        izz="6.867E-05" />
    </inertial>
    <visual>
      <origin
        xyz="0 0 0"
        rpy="0 0 0" />
      <geometry>
        <mesh
          filename="f52.STL" />
      </geometry>
      <material
        name="">
        <color
          rgba="0.6 0.8 0.8 1" />
      </material>
    </visual>
    <collision>
      <origin
        xyz="0 0 0"
        rpy="0 0 0" />
      <geometry>
        <mesh
          filename="f52.STL" />
      </geometry>
    </collision>
  </link>
  <joint
    name="f52_joint"
    type="revolute">
    <origin
      xyz="0.0092399 0.0031582 0.022073"
      rpy="1.8447 -0.25085 1.7172" />
    <parent
      link="f51" />
    <child
      link="f52" />
    <axis
      xyz="0 0 1" />
    <limit
      lower="0"
      upper="1.332"
      effort="0"
      velocity="0" />
  </joint>
  <link
    name="f53">
    <inertial>
      <origin
        xyz="0.021453 0.0041043 -5.93E-06"
        rpy="0 0 0" />
      <mass
        value="0.011849" />
      <inertia
        ixx="6.6E-07"
        ixy="-1E-08"
        ixz="-1E-08"
        iyy="1.94E-06"
        iyz="0"
        izz="1.88E-06" />
    </inertial>
    <visual>
      <origin
        xyz="0 0 0"
        rpy="0 0 0" />
      <geometry>
        <mesh
          filename="f53.STL" />
      </geometry>
      <material
        name="">
        <color
          rgba="0.55 0.8 0.75 1" />
      </material>
    </visual>
    <collision>
      <origin
        xyz="0 0 0"
        rpy="0 0 0" />
      <geometry>
        <mesh
          filename="f53.STL" />
      </geometry>
    </collision>
  </link>
  <joint
    name="f53_joint"
    type="revolute">
    <origin
      xyz="0.0654 0 0"
      rpy="0 0 0" />
    <parent
      link="f52" />
    <child
      link="f53" />
    <axis
      xyz="0 0 1" />
    <limit
      lower="0"
      upper="1.744"
      effort="0"
      velocity="0" />
  </joint>
  <link
    name="f54">
    <inertial>
      <origin
        xyz="0.013824 -0.0017677 -5.567E-05"
        rpy="0 0 0" />
      <mass
        value="0.010348" />
      <inertia
        ixx="5.5E-07"
        ixy="-1.5E-07"
        ixz="0"
        iyy="1.35E-06"
        iyz="0"
        izz="1.17E-06" />
    </inertial>
    <visual>
      <origin
        xyz="0 0 0"
        rpy="0 0 0" />
      <geometry>
        <mesh
          filename="f54.STL" />
      </geometry>
      <material
        name="">
        <color
          rgba="0.5 0.8 0.7 1" />
      </material>
    </visual>
    <collision>
      <origin
        xyz="0 0 0"
        rpy="0 0 0" />
      <geometry>
        <mesh
          filename="f54.STL" />
      </geometry>
    </collision>
  </link>
  <joint
    name="f54_joint"
    type="revolute">
    <origin
      xyz="0.035837 0.0034221 0"
      rpy="0 0 0" />
    <parent
      link="f53" />
    <child
      link="f54" />
    <axis
      xyz="0 0 1" />
    <limit
      lower="0"
      upper="1.744"
      effort="0"
      velocity="0" />
  </joint>
  <link
    name="f54_touch">
    <inertial>
      <origin
        xyz="-0.0069393 -0.0062876 -6.6426E-06"
        rpy="0 0 0" />
      <mass
        value="1.0348E-30" />
      <inertia
        ixx="3.82E-30"
        ixy="1.0071E-30"
        ixz="-4.036E-30"
        iyy="6.7691E-30"
        iyz="-1.7183E-30"
        izz="6.1259E-30" />
    </inertial>
    <!--visual>
      <origin
        xyz="0 0 0"
        rpy="0 0 0" />
      <geometry>
        <mesh
          filename="f54_touch.STL" />
      </geometry>
      <material
        name="">
        <color
          rgba="0.79216 0.81961 0.93333 1" />
      </material>
    </visual>
    <collision>
      <origin
        xyz="0 0 0"
        rpy="0 0 0" />
      <geometry>
        <mesh
          filename="f54_touch.STL" />
      </geometry>
    </collision-->
  </link>
  <joint
    name="f51_touch_joint"
    type="fixed">
    <origin
      xyz="0.024 0.0044004 0"
      rpy="0 0 0" />
    <parent
      link="f54" />
    <child
      link="f54_touch" />
    <axis
      xyz="0 0 0" />
  </joint>
  <link
    name="wrist">
    <inertial>
      <origin
        xyz="-0.0028852 -0.0083149 0.064459"
        rpy="0 0 0" />
      <mass
        value="9.1778E-30" />
      <inertia
        ixx="7.9132E-30"
        ixy="-2.1444E-30"
        ixz="1.1504E-30"
        iyy="5.5073E-30"
        iyz="-5.3465E-30"
        izz="5.0251E-30" />
    </inertial>
    <!--visual>
      <origin
        xyz="0 0 0"
        rpy="0 0 0" />
      <geometry>
        <mesh
          filename="wrist.STL" />
      </geometry>
      <material
        name="">
        <color
          rgba="0.79216 0.81961 0.93333 1" />
      </material>
    </visual>
    <collision>
      <origin
        xyz="0 0 0"
        rpy="0 0 0" />
      <geometry>
        <mesh
          filename="wrist.STL" />
      </geometry>
    </collision-->
  </link>
  <joint
    name="wrist_joint"
    type="fixed">
    <origin
      xyz="-0.026239 0.004298 -0.089754"
      rpy="0 0 0" />
    <parent
      link="base_link" />
    <child
      link="wrist" />
    <axis
      xyz="0 0 0" />
  </joint>
</robot>
