<mujoco model="freehand_right">
  <compiler angle="radian"/>

  <asset>
    <mesh name="right_palm" file="./description/meshes/palm.STL"/>
    <mesh name="right_f11" file="./description/meshes/f11.STL"/>
    <mesh name="right_f12" file="./description/meshes/f12.STL"/>
    <mesh name="right_f13" file="./description/meshes/f13.STL"/>
    <mesh name="right_f14" file="./description/meshes/f14.STL"/>
    <mesh name="right_f21" file="./description/meshes/f21.STL"/>
    <mesh name="right_f22" file="./description/meshes/f22.STL"/>
    <mesh name="right_f23" file="./description/meshes/f23.STL"/>
    <mesh name="right_f24" file="./description/meshes/f24.STL"/>
    <mesh name="right_f31" file="./description/meshes/f31.STL"/>
    <mesh name="right_f32" file="./description/meshes/f32.STL"/>
    <mesh name="right_f33" file="./description/meshes/f33.STL"/>
    <mesh name="right_f34" file="./description/meshes/f34.STL"/>
    <mesh name="right_f41" file="./description/meshes/f41.STL"/>
    <mesh name="right_f42" file="./description/meshes/f42.STL"/>
    <mesh name="right_f43" file="./description/meshes/f43.STL"/>
    <mesh name="right_f44" file="./description/meshes/f44.STL"/>
    <mesh name="right_f51" file="./description/meshes/f51.STL"/>
    <mesh name="right_f52" file="./description/meshes/f52.STL"/>
    <mesh name="right_f53" file="./description/meshes/f53.STL"/>
    <mesh name="right_f54" file="./description/meshes/f54.STL"/>
  </asset>

  <worldbody>
    <body name="right_hand" pos="0.0 -0.2 0.5">  
      <!-- <freejoint/> -->
      <geom type="mesh" rgba="0.2 0.2 0.2 1" mesh="right_palm"/>
      <body name="right_f11" pos="-0.022466 0.027654 0.043657" quat="0.5065 0.493412 0.506504 0.493412">
          <inertial pos="0 0.00069742 -0.0093798" quat="0.706804 0.0206991 -0.0206991 0.706804" mass="0.0033015" diaginertia="3.10586e-07 2e-07 1.39414e-07"/>
          <joint name="right_f11_joint" pos="0 0 0" axis="0 0 -1" range="-0.4 0.4"/>
          <geom type="mesh" rgba="0.913725 0.913725 0.847059 1" mesh="right_f11"/>
          <body name="right_f12" quat="0.499998 0.5 0.500002 0.5">
              <inertial pos="0.026032 -0.0074611 2.268e-05" quat="-0.330388 0.713877 -0.0698403 0.613471" mass="0.058465" diaginertia="1.66096e-05 1.57486e-05 2.27188e-06"/>
              <joint name="right_f12_joint" pos="0 0 0" axis="0 0 1" range="0 2.09"/>
              <geom type="mesh" rgba="0.913725 0.913725 0.847059 1" mesh="right_f12"/>
              <body name="right_f13" pos="0.048883 -0.018383 0">
                  <inertial pos="0.0090975 -0.0015069 0.0013415" quat="0.368759 0.472545 0.444032 0.665998" mass="0.014574" diaginertia="2.15877e-06 1.8024e-06 8.18837e-07"/>
                  <joint name="right_f13_joint" pos="0 0 0" axis="0 0 1" range="0 1.744"/>
                  <geom type="mesh" rgba="0.913725 0.913725 0.847059 1" mesh="right_f13"/>
                  <body name="right_f14" pos="0.0284 -0.0092477 0">
                      <inertial pos="0.007749 -0.0041898 -0.00072552" quat="-0.376065 0.718367 -0.0331381 0.584317" mass="0.0055228" diaginertia="5.13712e-07 4.74117e-07 1.4217e-07"/>
                      <joint name="right_f14_joint" pos="0 0 0" axis="0 0 1" range="0 1.744"/>
                      <geom type="mesh" rgba="0.913725 0.913725 0.847059 1" mesh="right_f14"/>
                  </body>
              </body>
          </body>
      </body>
      <body name="right_f21" pos="-0.022466 0.0022583 0.053546" quat="0.499998 0.5 0.500002 0.5">
          <inertial pos="0 0.00069742 -0.0093798" quat="0.706804 0.0206991 -0.0206991 0.706804" mass="0.0033015" diaginertia="3.10586e-07 2e-07 1.39414e-07"/>
          <joint name="right_f21_joint" pos="0 0 0" axis="0 0 -1" range="-0.4 0.4"/>
          <geom type="mesh" rgba="0.913725 0.913725 0.847059 1" mesh="right_f21"/>
          <body name="right_f22" quat="0.499998 0.5 0.500002 0.5">
              <inertial pos="0.026032 -0.0074611 2.268e-05" quat="-0.330388 0.713877 -0.0698403 0.613471" mass="0.058465" diaginertia="1.66096e-05 1.57486e-05 2.27188e-06"/>
              <joint name="right_f22_joint" pos="0 0 0" axis="0 0 1" range="0 2.09"/>
              <geom type="mesh" rgba="0.913725 0.913725 0.847059 1" mesh="right_f22"/>
              <body name="right_f23" pos="0.048883 -0.018383 0">
                  <inertial pos="0.0090975 -0.0015069 0.0013415" quat="0.368759 0.472545 0.444032 0.665998" mass="0.014574" diaginertia="2.15877e-06 1.8024e-06 8.18837e-07"/>
                  <joint name="right_f23_joint" pos="0 0 0" axis="0 0 1" range="0 1.744"/>
                  <geom type="mesh" rgba="0.913725 0.913725 0.847059 1" mesh="right_f23"/>
                  <body name="right_f24" pos="0.0284 -0.0092477 0">
                      <inertial pos="0.007749 -0.0041898 -0.00072552" quat="-0.376065 0.718367 -0.0331381 0.584317" mass="0.0055228" diaginertia="5.13712e-07 4.74117e-07 1.4217e-07"/>
                      <joint name="right_f24_joint" pos="0 0 0" axis="0 0 1" range="0 1.744"/>
                      <geom type="mesh" rgba="0.913725 0.913725 0.847059 1" mesh="right_f24"/>
                  </body>
              </body>
          </body>
      </body>
      <body name="right_f31" pos="-0.021466 -0.017542 0.047798" quat="0.499998 0.5 0.500002 0.5">
          <inertial pos="-6.964e-05 -0.00044078 -0.012759" quat="0.706754 0.0223246 -0.0223246 0.706754" mass="0.0085521" diaginertia="7.6253e-07 7.6e-07 1.2747e-07"/>
          <joint name="right_f31_joint" pos="0 0 0" axis="0 0 -1" range="-0.4 0.4"/>
          <geom type="mesh" rgba="0.913725 0.913725 0.847059 1" mesh="right_f31"/>
          <body name="right_f32" quat="0.499998 0.5 0.500002 0.5">
              <inertial pos="0.025132 0.0031733 -8.727e-05" quat="-0.0229244 0.706735 0.0229244 0.706735" mass="0.01244" diaginertia="2.41e-06 2.29779e-06 4.42207e-07"/>
              <joint name="right_f32_joint" pos="0 0 0" axis="0 0 1" range="0 1.744"/>
              <geom type="mesh" rgba="0.913725 0.913725 0.847059 1" mesh="right_f32"/>
              <body name="right_f33" pos="0.044995 0.00066781 0">
                  <inertial pos="0.010032 -0.00058707 -9.093e-05" quat="0.451397 0.451397 0.54428 0.54428" mass="0.0071009" diaginertia="7.05057e-07 7e-07 2.64943e-07"/>
                  <joint name="right_f33_joint" pos="0 0 0" axis="0 0 1" range="0 1.744"/>
                  <geom type="mesh" rgba="0.913725 0.913725 0.847059 1" mesh="right_f33"/>
                  <body name="right_f34" pos="0.024601 -0.0044465 0">
                      <inertial pos="0.010482 -0.0030354 -1.03e-05" quat="-0.0992524 0.700106 0.0992524 0.700106" mass="0.0049513" diaginertia="3.7e-07 3.37361e-07 1.12639e-07"/>
                      <joint name="right_f34_joint" pos="0 0 0" axis="0 0 1" range="0 1.744"/>
                      <geom type="mesh" rgba="0.913725 0.913725 0.847059 1" mesh="right_f34"/>
                  </body>
              </body>
          </body>
      </body>
      <body name="right_f41" pos="-0.021466 -0.034458 0.032384" quat="0.491196 0.50865 0.491199 0.50865">
          <inertial pos="-6.964e-05 -0.00044078 -0.012759" quat="0.706754 0.0223246 -0.0223246 0.706754" mass="0.0085521" diaginertia="7.6253e-07 7.6e-07 1.2747e-07"/>
          <joint name="right_f41_joint" pos="0 0 0" axis="0 0 -1" range="-0.4 0.4"/>
          <geom type="mesh" rgba="0.913725 0.913725 0.847059 1" mesh="right_f41"/>
          <body name="right_f42" quat="0.499998 0.5 0.500002 0.5">
              <inertial pos="0.021044 0.0035949 -7.944e-05" quat="-0.011899 0.707007 0.011899 0.707007" mass="0.0096409" diaginertia="1.35e-06 1.24101e-06 3.4899e-07"/>
              <joint name="right_f42_joint" pos="0 0 0" axis="0 0 1" range="0 1.6"/>
              <geom type="mesh" rgba="0.913725 0.913725 0.847059 1" mesh="right_f42"/>
              <body name="right_f43" pos="0.035975 0.001338 0">
                  <inertial pos="0.010032 -0.00058707 -9.093e-05" quat="0.451397 0.451397 0.54428 0.54428" mass="0.0071009" diaginertia="7.05057e-07 7e-07 2.64943e-07"/>
                  <joint name="right_f43_joint" pos="0 0 0" axis="0 0 1" range="0 1.744"/>
                  <geom type="mesh" rgba="0.913725 0.913725 0.847059 1" mesh="right_f43"/>
                  <body name="right_f44" pos="0.024621 -0.004339 0">
                      <inertial pos="0.010482 -0.0030354 -1.03e-05" quat="-0.0992524 0.700106 0.0992524 0.700106" mass="0.0049513" diaginertia="3.7e-07 3.37361e-07 1.12639e-07"/>
                      <joint name="right_f44_joint" pos="0 0 0" axis="0 0 1" range="0 1.744"/>
                      <geom type="mesh" rgba="0.913725 0.913725 0.847059 1" mesh="right_f44"/>
                  </body>
              </body>
          </body>
      </body>
      <body name="right_f51" pos="-0.00049657 0.0084524 -0.066754">
          <inertial pos="0.0053991 0.0016936 0.01157" quat="0.382167 0.6714 0.53871 0.336098" mass="0.022542" diaginertia="5.25338e-06 3.56442e-06 2.8022e-06"/>
          <joint name="right_f51_joint" pos="0 0 0" axis="0 0 -1" range="0 1.5"/>
          <geom type="mesh" rgba="0.913725 0.913725 0.847059 1" mesh="right_f51"/>
          <body name="right_f52" pos="0.0092399 0.0031582 0.022073" quat="0.31611 0.573949 0.549177 0.518712">
              <inertial pos="0.03317 -0.0064258 -0.00083733" quat="0.0733623 0.670395 0.154724 0.721975" mass="0.12909" diaginertia="6.93324e-05 6.44145e-05 1.53331e-05"/>
              <joint name="right_f52_joint" pos="0 0 0" axis="0 0 1" range="0 1.332"/>
              <geom type="mesh" rgba="0.913725 0.913725 0.847059 1" mesh="right_f52"/>
              <body name="right_f53" pos="0.0654 0 0">
                  <inertial pos="0.021453 0.0041043 -5.93e-06" quat="0.499752 0.496324 0.499565 0.504327" mass="0.011849" diaginertia="1.94008e-06 1.88008e-06 6.5984e-07"/>
                  <joint name="right_f53_joint" pos="0 0 0" axis="0 0 1" range="0 1.744"/>
                  <geom type="mesh" rgba="0.913725 0.913725 0.847059 1" mesh="right_f53"/>
                  <body name="right_f54" pos="0.035837 0.0034221 0">
                      <inertial pos="0.013824 -0.0017677 -5.567e-05" quat="0.453204 0.453204 0.542776 0.542776" mass="0.010348" diaginertia="1.3772e-06 1.17e-06 5.228e-07"/>
                      <joint name="right_f54_joint" pos="0 0 0" axis="0 0 1" range="0 1.744"/>
                      <geom type="mesh" rgba="0.913725 0.913725 0.847059 1" mesh="right_f54"/>
                  </body>
              </body>
          </body>
      </body>
    </body>
  </worldbody>
</mujoco>

